Traceback (most recent call last):
  File "/Library/Frameworks/Python.framework/Versions/3.9/lib/python3.9/site-packages/urllib3/connection.py", line 169, in _new_conn
    conn = connection.create_connection(
  File "/Library/Frameworks/Python.framework/Versions/3.9/lib/python3.9/site-packages/urllib3/util/connection.py", line 73, in create_connection
    for res in socket.getaddrinfo(host, port, family, socket.SOCK_STREAM):
  File "/Library/Frameworks/Python.framework/Versions/3.9/lib/python3.9/socket.py", line 954, in getaddrinfo
    for res in _socket.getaddrinfo(host, port, family, type, proto, flags):
socket.gaierror: [Errno 8] nodename nor servname provided, or not known

During handling of the above exception, another exception occurred:

Traceback (most recent call last):
  File "/Library/Frameworks/Python.framework/Versions/3.9/lib/python3.9/site-packages/urllib3/connectionpool.py", line 699, in urlopen
    httplib_response = self._make_request(
  File "/Library/Frameworks/Python.framework/Versions/3.9/lib/python3.9/site-packages/urllib3/connectionpool.py", line 382, in _make_request
    self._validate_conn(conn)
  File "/Library/Frameworks/Python.framework/Versions/3.9/lib/python3.9/site-packages/urllib3/connectionpool.py", line 1010, in _validate_conn
    conn.connect()
  File "/Library/Frameworks/Python.framework/Versions/3.9/lib/python3.9/site-packages/urllib3/connection.py", line 353, in connect
    conn = self._new_conn()
  File "/Library/Frameworks/Python.framework/Versions/3.9/lib/python3.9/site-packages/urllib3/connection.py", line 181, in _new_conn
    raise NewConnectionError(
urllib3.exceptions.NewConnectionError: <urllib3.connection.HTTPSConnection object at 0x7fd8502ee220>: Failed to establish a new connection: [Errno 8] nodename nor servname provided, or not known

During handling of the above exception, another exception occurred:

Traceback (most recent call last):
  File "/Library/Frameworks/Python.framework/Versions/3.9/lib/python3.9/site-packages/requests/adapters.py", line 439, in send
    resp = conn.urlopen(
  File "/Library/Frameworks/Python.framework/Versions/3.9/lib/python3.9/site-packages/urllib3/connectionpool.py", line 755, in urlopen
    retries = retries.increment(
  File "/Library/Frameworks/Python.framework/Versions/3.9/lib/python3.9/site-packages/urllib3/util/retry.py", line 574, in increment
    raise MaxRetryError(_pool, url, error or ResponseError(cause))
urllib3.exceptions.MaxRetryError: HTTPSConnectionPool(host='docs.google.com', port=443): Max retries exceeded with url: /forms/d/e/1FAIpQLSdf1izu-_q93djsroEalN5iAp5JRwkBdPtO1npNWMl-xZhDXA/viewform?usp=pp_url&entry.790589354=%E4%B8%89%E6%B5%A6%E5%8B%87%E5%88%A9&entry.2145502044=36.5&entry.581723830=%E3%81%AA%E3%81%97&entry.902848957=%E3%81%AA%E3%81%97&entry.1879384200=%E3%81%84%E3%81%A4%E3%82%82%E9%80%9A%E3%82%8A&entry.1693817462=%E3%81%84%E3%81%A4%E3%82%82%E9%80%9A%E3%82%8A&entry.1895494867=%E3%81%AA%E3%81%97&entry.227844412=%E3%81%84%E3%81%84%E3%81%88 (Caused by NewConnectionError('<urllib3.connection.HTTPSConnection object at 0x7fd8502ee220>: Failed to establish a new connection: [Errno 8] nodename nor servname provided, or not known'))

During handling of the above exception, another exception occurred:

Traceback (most recent call last):
  File "/Users/miurayuuri/python_cron/MYPY_001/gf_club_bt002.py", line 31, in <module>
    r = requests.get(url, params=params)
  File "/Library/Frameworks/Python.framework/Versions/3.9/lib/python3.9/site-packages/requests/api.py", line 75, in get
    return request('get', url, params=params, **kwargs)
  File "/Library/Frameworks/Python.framework/Versions/3.9/lib/python3.9/site-packages/requests/api.py", line 61, in request
    return session.request(method=method, url=url, **kwargs)
  File "/Library/Frameworks/Python.framework/Versions/3.9/lib/python3.9/site-packages/requests/sessions.py", line 542, in request
    resp = self.send(prep, **send_kwargs)
  File "/Library/Frameworks/Python.framework/Versions/3.9/lib/python3.9/site-packages/requests/sessions.py", line 655, in send
    r = adapter.send(request, **kwargs)
  File "/Library/Frameworks/Python.framework/Versions/3.9/lib/python3.9/site-packages/requests/adapters.py", line 516, in send
    raise ConnectionError(e, request=request)
requests.exceptions.ConnectionError: HTTPSConnectionPool(host='docs.google.com', port=443): Max retries exceeded with url: /forms/d/e/1FAIpQLSdf1izu-_q93djsroEalN5iAp5JRwkBdPtO1npNWMl-xZhDXA/viewform?usp=pp_url&entry.790589354=%E4%B8%89%E6%B5%A6%E5%8B%87%E5%88%A9&entry.2145502044=36.5&entry.581723830=%E3%81%AA%E3%81%97&entry.902848957=%E3%81%AA%E3%81%97&entry.1879384200=%E3%81%84%E3%81%A4%E3%82%82%E9%80%9A%E3%82%8A&entry.1693817462=%E3%81%84%E3%81%A4%E3%82%82%E9%80%9A%E3%82%8A&entry.1895494867=%E3%81%AA%E3%81%97&entry.227844412=%E3%81%84%E3%81%84%E3%81%88 (Caused by NewConnectionError('<urllib3.connection.HTTPSConnection object at 0x7fd8502ee220>: Failed to establish a new connection: [Errno 8] nodename nor servname provided, or not known'))


====== WebDriver manager ======
Current google-chrome version is 96.0.4664
Get LATEST chromedriver version for 96.0.4664 google-chrome
Trying to download new driver from https://chromedriver.storage.googleapis.com/96.0.4664.45/chromedriver_mac64.zip
Driver has been saved in cache [/Users/miurayuuri/.wdm/drivers/chromedriver/mac64/96.0.4664.45]
done
